[2022-11-29 03:13:15,364] {taskinstance.py:1037} INFO - Dependencies all met for <TaskInstance: Covid_dags.creatableLoad manual__2022-11-29T03:08:09.845419+00:00 [queued]>
[2022-11-29 03:13:15,372] {taskinstance.py:1037} INFO - Dependencies all met for <TaskInstance: Covid_dags.creatableLoad manual__2022-11-29T03:08:09.845419+00:00 [queued]>
[2022-11-29 03:13:15,372] {taskinstance.py:1243} INFO - 
--------------------------------------------------------------------------------
[2022-11-29 03:13:15,372] {taskinstance.py:1244} INFO - Starting attempt 2 of 2
[2022-11-29 03:13:15,372] {taskinstance.py:1245} INFO - 
--------------------------------------------------------------------------------
[2022-11-29 03:13:15,381] {taskinstance.py:1264} INFO - Executing <Task(PythonOperator): creatableLoad> on 2022-11-29 03:08:09.845419+00:00
[2022-11-29 03:13:15,418] {standard_task_runner.py:52} INFO - Started process 3078 to run task
[2022-11-29 03:13:15,421] {standard_task_runner.py:76} INFO - Running: ['***', 'tasks', 'run', 'Covid_dags', 'creatableLoad', 'manual__2022-11-29T03:08:09.845419+00:00', '--job-id', '942', '--raw', '--subdir', 'DAGS_FOLDER/dbtest.py', '--cfg-path', '/tmp/tmpw0dl_e9k', '--error-file', '/tmp/tmpejfwn13s']
[2022-11-29 03:13:15,422] {standard_task_runner.py:77} INFO - Job 942: Subtask creatableLoad
[2022-11-29 03:13:15,471] {logging_mixin.py:109} INFO - Running <TaskInstance: Covid_dags.creatableLoad manual__2022-11-29T03:08:09.845419+00:00 [running]> on host acb48b0a6e0d
[2022-11-29 03:13:15,525] {taskinstance.py:1431} INFO - Exporting the following env vars:
AIRFLOW_CTX_DAG_OWNER=***
AIRFLOW_CTX_DAG_ID=Covid_dags
AIRFLOW_CTX_TASK_ID=creatableLoad
AIRFLOW_CTX_EXECUTION_DATE=2022-11-29T03:08:09.845419+00:00
AIRFLOW_CTX_DAG_RUN_ID=manual__2022-11-29T03:08:09.845419+00:00
[2022-11-29 03:13:15,542] {taskinstance.py:1718} ERROR - Task failed with exception
Traceback (most recent call last):
  File "/home/airflow/.local/lib/python3.7/site-packages/airflow/models/taskinstance.py", line 1334, in _run_raw_task
    self._execute_task_with_callbacks(context)
  File "/home/airflow/.local/lib/python3.7/site-packages/airflow/models/taskinstance.py", line 1460, in _execute_task_with_callbacks
    result = self._execute_task(context, self.task)
  File "/home/airflow/.local/lib/python3.7/site-packages/airflow/models/taskinstance.py", line 1516, in _execute_task
    result = execute_callable(context=context)
  File "/home/airflow/.local/lib/python3.7/site-packages/airflow/operators/python.py", line 174, in execute
    return_value = self.execute_callable()
  File "/home/airflow/.local/lib/python3.7/site-packages/airflow/operators/python.py", line 188, in execute_callable
    return self.python_callable(*self.op_args, **self.op_kwargs)
  File "/opt/airflow/dags/dbtest.py", line 128, in creatableLoad
    row.split(",")[10])
psycopg2.errors.DatetimeFieldOverflow: date/time field value out of range: ""1583107200000""
LINE 3:                     VALUES ('"1583107200000"', '"2020-03-02"...
                                    ^
HINT:  Perhaps you need a different "datestyle" setting.

[2022-11-29 03:13:15,558] {taskinstance.py:1282} INFO - Marking task as FAILED. dag_id=Covid_dags, task_id=creatableLoad, execution_date=20221129T030809, start_date=20221129T031315, end_date=20221129T031315
[2022-11-29 03:13:15,572] {standard_task_runner.py:92} ERROR - Failed to execute job 942 for task creatableLoad
Traceback (most recent call last):
  File "/home/airflow/.local/lib/python3.7/site-packages/airflow/task/task_runner/standard_task_runner.py", line 85, in _start_by_fork
    args.func(args, dag=self.dag)
  File "/home/airflow/.local/lib/python3.7/site-packages/airflow/cli/cli_parser.py", line 48, in command
    return func(*args, **kwargs)
  File "/home/airflow/.local/lib/python3.7/site-packages/airflow/utils/cli.py", line 92, in wrapper
    return f(*args, **kwargs)
  File "/home/airflow/.local/lib/python3.7/site-packages/airflow/cli/commands/task_command.py", line 298, in task_run
    _run_task_by_selected_method(args, dag, ti)
  File "/home/airflow/.local/lib/python3.7/site-packages/airflow/cli/commands/task_command.py", line 107, in _run_task_by_selected_method
    _run_raw_task(args, ti)
  File "/home/airflow/.local/lib/python3.7/site-packages/airflow/cli/commands/task_command.py", line 184, in _run_raw_task
    error_file=args.error_file,
  File "/home/airflow/.local/lib/python3.7/site-packages/airflow/utils/session.py", line 70, in wrapper
    return func(*args, session=session, **kwargs)
  File "/home/airflow/.local/lib/python3.7/site-packages/airflow/models/taskinstance.py", line 1334, in _run_raw_task
    self._execute_task_with_callbacks(context)
  File "/home/airflow/.local/lib/python3.7/site-packages/airflow/models/taskinstance.py", line 1460, in _execute_task_with_callbacks
    result = self._execute_task(context, self.task)
  File "/home/airflow/.local/lib/python3.7/site-packages/airflow/models/taskinstance.py", line 1516, in _execute_task
    result = execute_callable(context=context)
  File "/home/airflow/.local/lib/python3.7/site-packages/airflow/operators/python.py", line 174, in execute
    return_value = self.execute_callable()
  File "/home/airflow/.local/lib/python3.7/site-packages/airflow/operators/python.py", line 188, in execute_callable
    return self.python_callable(*self.op_args, **self.op_kwargs)
  File "/opt/airflow/dags/dbtest.py", line 128, in creatableLoad
    row.split(",")[10])
psycopg2.errors.DatetimeFieldOverflow: date/time field value out of range: ""1583107200000""
LINE 3:                     VALUES ('"1583107200000"', '"2020-03-02"...
                                    ^
HINT:  Perhaps you need a different "datestyle" setting.

[2022-11-29 03:13:15,593] {local_task_job.py:154} INFO - Task exited with return code 1
[2022-11-29 03:13:15,622] {local_task_job.py:264} INFO - 0 downstream tasks scheduled from follow-on schedule check
