[2022-11-28 19:01:18,341] {taskinstance.py:1037} INFO - Dependencies all met for <TaskInstance: using_pandas_demo.getDataToLocal manual__2022-11-28T19:01:17.221697+00:00 [queued]>
[2022-11-28 19:01:18,355] {taskinstance.py:1037} INFO - Dependencies all met for <TaskInstance: using_pandas_demo.getDataToLocal manual__2022-11-28T19:01:17.221697+00:00 [queued]>
[2022-11-28 19:01:18,355] {taskinstance.py:1243} INFO - 
--------------------------------------------------------------------------------
[2022-11-28 19:01:18,355] {taskinstance.py:1244} INFO - Starting attempt 1 of 2
[2022-11-28 19:01:18,355] {taskinstance.py:1245} INFO - 
--------------------------------------------------------------------------------
[2022-11-28 19:01:18,373] {taskinstance.py:1264} INFO - Executing <Task(PythonOperator): getDataToLocal> on 2022-11-28 19:01:17.221697+00:00
[2022-11-28 19:01:18,378] {standard_task_runner.py:52} INFO - Started process 308 to run task
[2022-11-28 19:01:18,382] {standard_task_runner.py:76} INFO - Running: ['***', 'tasks', 'run', 'using_pandas_demo', 'getDataToLocal', 'manual__2022-11-28T19:01:17.221697+00:00', '--job-id', '394', '--raw', '--subdir', 'DAGS_FOLDER/dbtest.py', '--cfg-path', '/tmp/tmp3jxx9zd_', '--error-file', '/tmp/tmp_16nvm80']
[2022-11-28 19:01:18,383] {standard_task_runner.py:77} INFO - Job 394: Subtask getDataToLocal
[2022-11-28 19:01:18,445] {logging_mixin.py:109} INFO - Running <TaskInstance: using_pandas_demo.getDataToLocal manual__2022-11-28T19:01:17.221697+00:00 [running]> on host acb48b0a6e0d
[2022-11-28 19:01:18,504] {taskinstance.py:1431} INFO - Exporting the following env vars:
AIRFLOW_CTX_DAG_OWNER=***
AIRFLOW_CTX_DAG_ID=using_pandas_demo
AIRFLOW_CTX_TASK_ID=getDataToLocal
AIRFLOW_CTX_EXECUTION_DATE=2022-11-28T19:01:17.221697+00:00
AIRFLOW_CTX_DAG_RUN_ID=manual__2022-11-28T19:01:17.221697+00:00
[2022-11-28 19:01:18,506] {taskinstance.py:1718} ERROR - Task failed with exception
Traceback (most recent call last):
  File "/home/airflow/.local/lib/python3.7/site-packages/airflow/models/taskinstance.py", line 1334, in _run_raw_task
    self._execute_task_with_callbacks(context)
  File "/home/airflow/.local/lib/python3.7/site-packages/airflow/models/taskinstance.py", line 1460, in _execute_task_with_callbacks
    result = self._execute_task(context, self.task)
  File "/home/airflow/.local/lib/python3.7/site-packages/airflow/models/taskinstance.py", line 1516, in _execute_task
    result = execute_callable(context=context)
  File "/home/airflow/.local/lib/python3.7/site-packages/airflow/operators/python.py", line 174, in execute
    return_value = self.execute_callable()
  File "/home/airflow/.local/lib/python3.7/site-packages/airflow/operators/python.py", line 188, in execute_callable
    return self.python_callable(*self.op_args, **self.op_kwargs)
  File "/opt/airflow/dags/dbtest.py", line 39, in getDataToLocal
    response = request.get(url)
NameError: name 'request' is not defined
[2022-11-28 19:01:18,520] {taskinstance.py:1282} INFO - Marking task as UP_FOR_RETRY. dag_id=using_pandas_demo, task_id=getDataToLocal, execution_date=20221128T190117, start_date=20221128T190118, end_date=20221128T190118
[2022-11-28 19:01:18,537] {standard_task_runner.py:92} ERROR - Failed to execute job 394 for task getDataToLocal
Traceback (most recent call last):
  File "/home/airflow/.local/lib/python3.7/site-packages/airflow/task/task_runner/standard_task_runner.py", line 85, in _start_by_fork
    args.func(args, dag=self.dag)
  File "/home/airflow/.local/lib/python3.7/site-packages/airflow/cli/cli_parser.py", line 48, in command
    return func(*args, **kwargs)
  File "/home/airflow/.local/lib/python3.7/site-packages/airflow/utils/cli.py", line 92, in wrapper
    return f(*args, **kwargs)
  File "/home/airflow/.local/lib/python3.7/site-packages/airflow/cli/commands/task_command.py", line 298, in task_run
    _run_task_by_selected_method(args, dag, ti)
  File "/home/airflow/.local/lib/python3.7/site-packages/airflow/cli/commands/task_command.py", line 107, in _run_task_by_selected_method
    _run_raw_task(args, ti)
  File "/home/airflow/.local/lib/python3.7/site-packages/airflow/cli/commands/task_command.py", line 184, in _run_raw_task
    error_file=args.error_file,
  File "/home/airflow/.local/lib/python3.7/site-packages/airflow/utils/session.py", line 70, in wrapper
    return func(*args, session=session, **kwargs)
  File "/home/airflow/.local/lib/python3.7/site-packages/airflow/models/taskinstance.py", line 1334, in _run_raw_task
    self._execute_task_with_callbacks(context)
  File "/home/airflow/.local/lib/python3.7/site-packages/airflow/models/taskinstance.py", line 1460, in _execute_task_with_callbacks
    result = self._execute_task(context, self.task)
  File "/home/airflow/.local/lib/python3.7/site-packages/airflow/models/taskinstance.py", line 1516, in _execute_task
    result = execute_callable(context=context)
  File "/home/airflow/.local/lib/python3.7/site-packages/airflow/operators/python.py", line 174, in execute
    return_value = self.execute_callable()
  File "/home/airflow/.local/lib/python3.7/site-packages/airflow/operators/python.py", line 188, in execute_callable
    return self.python_callable(*self.op_args, **self.op_kwargs)
  File "/opt/airflow/dags/dbtest.py", line 39, in getDataToLocal
    response = request.get(url)
NameError: name 'request' is not defined
[2022-11-28 19:01:18,554] {local_task_job.py:154} INFO - Task exited with return code 1
[2022-11-28 19:01:18,597] {local_task_job.py:264} INFO - 0 downstream tasks scheduled from follow-on schedule check
